Workbook
Name DATAJABATAN: [1]DATABASE!$A$2:$N$7

Sheet DATA
A1: DATA
A2: 1 | B2: KODE JABATAN | C2: : | D2: 23.1.1.0.8 | F2: 1
A3: 2 | B3: NAMA JABATAN | C3: : | D3: Pengadministrasi Perkantoran | F3: 2
A4: 3 | B4: UNIT KERJA ESELON IV | C4: : | D4: - | F4: 3
A5: 4 | B5: UNIT KERJA ESELON III | C5: : | D5: Sekretariat Dinas Penanaman Modal dan Pelayanan Terpadu Satu Pintu | F5: 4
A6: 5 | B6: PERANGKAT DAERAH | C6: : | D6: Dinas Penanaman Modal dan Pelayanan Terpadu Satu Pintu | F6: 5
A7: 6 | B7: ATASAN LANGSUNG | C7: : | D7: Sekretaris Dinas Penanaman Modal dan Pelayanan Terpadu Satu Pintu | F7: 8
A8: 7 | B8: ATASAN ATASAN LANGSUNG | C8: : | D8: Kepala Dinas Penanaman Modal dan Pelayanan Terpadu Satu Pintu | F8: 9
A9: 8 | B9: BIDANG TUGAS-NOMENKLATUR JABATAN | C9: : | D9: perencanaan, evaluasi, dan pelaporan | F9: 10
A10: 9 | B10: URUSAN-KEGIATAN | C10: : | F10: 11
A11: 10 | B11: PENDIDIKAN | C11: : | D11: SLTA Sederajat/D-3(Diploma-Tiga) bidang yang relevan dengan tugas jabatan | F11: 13
A12: 11 | B12: TUGAS-IKHTISAR JABATAN | C12: : | D12: Melaksanakan kegiatan dukungan administrasi perkantoran, pemerintahan, dan pelayanan publik dalam lingkup tugas perencanaan, evaluasi, dan pelaporan | F12: 14
A13: 12 | B13: KEBUTUHAN SDM | C13: : | D13: 1 | F13: 7
A14: 13 | B14: LEVEL FAKTOR 1 (STRUKTURAL) | C14: : | D14: 0 | F14: 16
A15: 14 | B15: LEVEL FAKTOR 2 | C15: : | D15: 0 | F15: 17
A16: 15 | B16: LEVEL FAKTOR 3 | C16: : | D16: 0 | F16: 18
A17: 16 | B17: LEVEL FAKTOR 4A | C17: : | D17: 0 | F17: 19
A18: 17 | B18: LEVEL FAKTOR 4B | C18: : | D18: 0 | F18: 20
A19: 18 | B19: LEVEL FAKTOR 5 | C19: : | D19: 0 | F19: 21
A20: 19 | B20: LEVEL FAKTOR 6 | C20: : | D20: 0 | F20: 22
A21: 20 | B21: LEVEL FAKTOR 1 (JF-PELAKSANA) | C21: : | D21: 3 | F21: 23
A22: 21 | B22: LEVEL FAKTOR 2 | C22: : | D22: 1 | F22: 24
A23: 22 | B23: LEVEL FAKTOR 3 | C23: : | D23: 1 | F23: 25
A24: 23 | B24: LEVEL FAKTOR 4 | C24: : | D24: 1 | F24: 26
... A30: 29 | B30: KELAS JABATAN | C30: : | D30: 5 | F30: 15
A31: 30 | B31: PANGKAT-GOL | C31: : | D31: Minimal Pengatur Muda (II/a) | F31: 32
A32: 31 | B32: DIKLAT PENJENJANGAN JF | C32: : | D32: - | F32: 33
A33: 32 | B33: PENGALAMAN KERJA KHUSUS | C33: : | D33: - | F33: 34
A34: 33 | B34: URTUG_1 | C34: : | D34: Melakukan penatausahaan surat dan dokumen yang meliputi penerimaan, penelitian, verifikasi, pencatatan, dan distribusi surat dan dokumen dalam lingkup tugas perencanaan, evaluasi, dan pelaporan | F34: 35
A35: 34 | B35: URTUG_2 | C35: : | D35: Menyusun dan menyediakan surat dan dokumen sesuai tata naskah dinas yang berlaku dalam lingkup tugas perencanaan, evaluasi, dan pelaporan | F35: 36
A36: 35 | B36: URTUG_3 | C36: : | D36: Melakukan penyimpanan dan pengarsipan sesuai dengan tata kelola arsip terhadap surat dan dokumen dalam lingkup tugas perencanaan, evaluasi, dan pelaporan | F36: 37
A37: 36 | B37: URTUG_4 | C37: : | D37: Melakukan kegiatan pelayanan publik dalam lingkup tugas perencanaan, evaluasi, dan pelaporan | F37: 38
A38: 37 | B38: URTUG_5 | C38: : | D38: Melaksanakan pemberian dukungan teknis terhadap pelaksanaan tugas dan fungsi unit organisasi berupa penyiapan dan penyusunan dokumen, data, bahan, dan perlengkapan kegiatan dalam rangka pencapaian target kinerja organisasi. | F38: 39
A39: 38 | B39: URTUG_6 | C39: : | D39: Menyusun laporan pelaksanaan tugas dan menyampaikan kepada pimpinan sebagai wujud akuntabilitas dan pertanggungjawaban pelaksanaan tugas. | F39: 40
A40: 39 | B40: URTUG_7 | C40: : | D40: Melaksanakan tugas kedinasan lain yang diberikan oleh pimpinan, baik lisan maupun tertulis sebagai wujud loyalitas dan kerjasama yang baik. | F40: 41
A41: 40 | B41: URTUG_8 | C41: : | D41: - | F41: 42
A42: 41 | B42: URTUG_9 | C42: : | D42: - | F42: 43
... A47: 46 | B47: URTUG_14 | C47: : | D47: - | F47: 48
A48: 47 | B48: JM HASIL-1 | C48: : | D48: 240 | F48: 49
A49: 48 | B49: WAKTU PENYELESAIAN-1 | C49: : | D49: 1,5 | F49: 50
...

Sheet URAIAN JABATAN
A5: PEMERINTAH KOTA SEMARANG
A7: URAIAN JABATAN
A9: 1. | B9: Nama Jabatan | F9: : | G9: =DATA!D3 -> Pengadministrasi Perkantoran
A10: 2. | B10: Kode Jabatan | F10: : | G10: =DATA!D2 -> 23.1.1.0.8
A11: 3. | B11: Unit Kerja | F11: :
B12: Eselon II/ Perangkat Daerah/UOBK | F12: : | G12: =DATA!D6 -> Dinas Penanaman Modal dan Pelayanan Terpadu Satu Pintu
B13: Eselon III | F13: : | G13: =DATA!D5 -> Sekretariat Dinas Penanaman Modal dan Pelayanan Terpadu Satu Pintu
B14: Eselon IV | F14: : | G14: =DATA!D4 -> -
A15: 4. | B15: Kedudukan Dalam Struktur Organisasi | K15: :
G17: =DATA!D8 -> Kepala Dinas Penanaman Modal dan Pelayanan Terpadu Satu Pintu
G22: =DATA!D7 -> Sekretaris Dinas Penanaman Modal dan Pelayanan Terpadu Satu Pintu
G27: =DATA!D3 -> Pengadministrasi Perkantoran
A32: 5. | B32: Ikhtisar Jabatan | F32: :
B33: =DATA!D12&"." -> Melaksanakan kegiatan dukungan administrasi perkantoran, pemerintahan, dan pelayanan publik dalam lingkup tugas perencanaan, evaluasi, dan pelaporan.
A34: 6. | B34: Uraian Tugas | F34: :
B35: a. | C35: =DATA!D34 -> Melakukan penatausahaan surat dan dokumen yang meliputi penerimaan, penelitian, verifikasi, pencatatan, dan distribusi surat dan dokumen dalam lingkup tugas perencanaan, evaluasi, dan pelaporan
B36: b. | C36: =DATA!D35 -> Menyusun dan menyediakan surat dan dokumen sesuai tata naskah dinas yang berlaku dalam lingkup tugas perencanaan, evaluasi, dan pelaporan
B37: c. | C37: =DATA!D36 -> Melakukan penyimpanan dan pengarsipan sesuai dengan tata kelola arsip terhadap surat dan dokumen dalam lingkup tugas perencanaan, evaluasi, dan pelaporan
B38: d. | C38: =DATA!D37 -> Melakukan kegiatan pelayanan publik dalam lingkup tugas perencanaan, evaluasi, dan pelaporan
B39: e. | C39: =DATA!D38 -> Melaksanakan pemberian dukungan teknis terhadap pelaksanaan tugas dan fungsi unit organisasi berupa penyiapan dan penyusunan dokumen, data, bahan, dan perlengkapan kegiatan dalam rangka pencapaian target kinerja organisasi.
B40: f. | C40: =DATA!D39 -> Menyusun laporan pelaksanaan tugas dan menyampaikan kepada pimpinan sebagai wujud akuntabilitas dan pertanggungjawaban pelaksanaan tugas.
B41: g. | C41: =DATA!D40 -> Melaksanakan tugas kedinasan lain yang diberikan oleh pimpinan, baik lisan maupun tertulis sebagai wujud loyalitas dan kerjasama yang baik.
C42: =Y42 -> 0
A43: 7. | B43: Bahan Kerja | E43: :
B45: No | C45: Bahan Kerja | N45: Penggunaan Dalam Tugas
B46: 1 | C46: Surat/dokumen yang terkait dengan bidang tugas. | N46: Dasar dan acuan dalam pelaksanaan tugas.
B47: 2 | C47: Data primer dan sekunder yang terkait dengan pelaksanaan tugas. | N47: Bahan dan materi penyusunan dokumen.
B48: 3 | C48: Materi rapat/sosialisasi/bimbingan teknis. | N48: Referensi dalam pelaksanaan tugas.
B49: 4 | C49: Buku/Karya Ilmiah | N49: Referensi dalam pelaksanaan tugas.
B50: 5 | C50: Kajian yang terkait dengan bidang tugas. | N50: Referensi dalam pelaksanaan tugas.
B51: 6 | C51: Informasi yang terkait dengan bidang tugas. | N51: Referensi dalam pelaksanaan tugas.
A53: 8. | B53: Perangkat Kerja | G53: :
B55: No | C55: Perangkat Kerja | N55: Digunakan Untuk Tugas
B56: 1 | C56: Peraturan Perundang-undangan terkait pelaksanaan tugas. | N56: Pedoman pelaksanaan tugas.
B57: 2 | C57: Petunjuk pelaksanaan dan petunjuk teknis | N57: Dasar dan acuan dalam pelaksanaan tugas.
B58: 3 | C58: SOP yang terkait dengan pelaksanaan tugas. | N58: Dasar dan acuan dalam pelaksanaan tugas.
B59: 4 | C59: Disposisi pimpinan. | N59: Petunjuk pelaksanaan tugas.
A61: 9. | B61: Hasil Kerja | E61: :
B63: No | C63: Hasil Kerja | Q63: Jumlah Satuan | T63: Waktu Yg diperlukan (jam)
B65: 1 | C65: =DATA!D76 -> Laporan kegiatan penatausahaan surat dan dokumen dalam lingkup tugas perencanaan, evaluasi, dan pelaporan | Q65: =DATA!$D48 -> 240 | T65: =DATA!D49 -> 1,5
...

Sheet ABK
A1: ANALISIS BEBAN KERJA (ABK) | P1: =DATA!D13 -> 1
A3: 1. | B3: NAMA JABATAN | E3: : | F3: ='URAIAN JABATAN'!G9 -> Pengadministrasi Perkantoran
A4: 2. | B4: UNIT KERJA | E4: : | F4: =IF(P4="-",Q4,(P4&", "&Q4)) -> Sekretariat Dinas Penanaman Modal dan Pelayanan Terpadu Satu Pintu | P4: =DATA!D4 -> - | Q4: =DATA!D5 -> Sekretariat Dinas Penanaman Modal dan Pelayanan Terpadu Satu Pintu
A5: 3. | B5: PERANGKAT DAERAH/UOBK | E5: : | F5: =DATA!D6 -> Dinas Penanaman Modal dan Pelayanan Terpadu Satu Pintu
A6: 4. | B6: IKHTISAR JABATAN | E6: : | F6: ='URAIAN JABATAN'!B33 -> Melaksanakan kegiatan dukungan administrasi perkantoran, pemerintahan, dan pelayanan publik dalam lingkup tugas perencanaan, evaluasi, dan pelaporan.
A8: No | B8: Uraian Jabatan | J8: Satuan Hasil | K8: Jumlah Hasil | L8: Waktu Penyelesaian (Jam) | M8: Waktu Efektif (Jam) | N8: Kebutuhan Pegawai | O8: Ket
A9: 1 | B9: 2 | J9: 3 | K9: 4 | L9: 5 | M9: 6 | N9: 7 | O9: 8
A10: 1 | B10: =DATA!D34 -> Melakukan penatausahaan surat dan dokumen yang meliputi penerimaan, penelitian, verifikasi, pencatatan, dan distribusi surat dan dokumen dalam lingkup tugas perencanaan, evaluasi, dan pelaporan | J10: Dokumen/ laporan | K10: =DATA!D48 -> 240 | L10: =DATA!D49 -> 1,5 | M10: 1250 | N10: =K10*L10/M10 -> #VALUE! | Q10: =SUM(K10*L10) -> #VALUE!
A11: 2 | B11: =DATA!D35 -> Menyusun dan menyediakan surat dan dokumen sesuai tata naskah dinas yang berlaku dalam lingkup tugas perencanaan, evaluasi, dan pelaporan | J11: Dokumen/ laporan | K11: =DATA!D50 -> 48 | L11: =DATA!D51 -> 4,5 | M11: 1250 | N11: =K11*L11/M11 -> #VALUE! | Q11: =SUM(K11*L11) -> #VALUE!
A12: 3 | B12: =DATA!D36 -> Melakukan penyimpanan dan pengarsipan sesuai dengan tata kelola arsip terhadap surat dan dokumen dalam lingkup tugas perencanaan, evaluasi, dan pelaporan | J12: Dokumen/ laporan | K12: =DATA!D52 -> 12 | L12: =DATA!D53 -> 3 | M12: 1250 | N12: =K12*L12/M12 -> 0.0288 | Q12: =SUM(K12*L12) -> 36
A13: 4 | B13: =DATA!D37 -> Melakukan kegiatan pelayanan publik dalam lingkup tugas perencanaan, evaluasi, dan pelaporan | J13: Dokumen/ laporan | K13: =DATA!D54 -> 240 | L13: =DATA!D55 -> 1,5 | M13: 1250 | N13: =K13*L13/M13 -> #VALUE! | Q13: =SUM(K13*L13) -> #VALUE!
A14: 5 | B14: =DATA!D38 -> Melaksanakan pemberian dukungan teknis terhadap pelaksanaan tugas dan fungsi unit organisasi berupa penyiapan dan penyusunan dokumen, data, bahan, dan perlengkapan kegiatan dalam rangka pencapaian target kinerja organisasi. | J14: Dokumen/ laporan | K14: =DATA!D56 -> 240 | L14: =DATA!D57 -> 1 | M14: 1250 | N14: =K14*L14/M14 -> 0.192 | Q14: =SUM(K14*L14) -> 240
A15: 6 | B15: =DATA!D39 -> Menyusun laporan pelaksanaan tugas dan menyampaikan kepada pimpinan sebagai wujud akuntabilitas dan pertanggungjawaban pelaksanaan tugas. | J15: Dokumen/ laporan | K15: =DATA!D58 -> 12 | L15: =DATA!D59 -> 3 | M15: 1250 | N15: =K15*L15/M15 -> 0.0288 | Q15: =SUM(K15*L15) -> 36
A16: 7 | B16: =DATA!D40 -> Melaksanakan tugas kedinasan lain yang diberikan oleh pimpinan, baik lisan maupun tertulis sebagai wujud loyalitas dan kerjasama yang baik. | J16: Dokumen/ laporan | K16: =DATA!D60 -> 2 | L16: =DATA!D61 -> 1,5 | M16: 1250 | N16: =K16*L16/M16 -> #VALUE! | Q16: =SUM(K16*L16) -> #VALUE!
A17: Jumlah | N17: =SUM(N10:N16) -> #VALUE!
A18: Jumlah Pegawai | N18: =DATA!D13 -> 1
I19: Jumlah Beban Kerja Jabatan | L19: =SUM(Q10:Q16) -> #VALUE!

Sheet INFOFAK
A5: PEMERINTAH KOTA SEMARANG
A7: INFORMASI FAKTOR JABATAN PELAKSANA
A9: Nama Jabatan | G9: : | H9: ='URAIAN JABATAN'!G9 -> Pengadministrasi Perkantoran
A10: Unit Organisasi | G10: :
A11: Eselon IV | G11: : | H11: =DATA!D4 -> -
A12: Eselon III | G12: : | H12: =DATA!D5 -> Sekretariat Dinas Penanaman Modal dan Pelayanan Terpadu Satu Pintu
A13: Perangkat Daerah/UOBK | G13: : | H13: =DATA!D6 -> Dinas Penanaman Modal dan Pelayanan Terpadu Satu Pintu
A15: I. | B15: PERAN JABATAN
B16: ="Jabatan ini "&LOWER('URAIAN JABATAN'!B33) -> Jabatan ini melaksanakan kegiatan dukungan administrasi perkantoran, pemerintahan, dan pelayanan publik dalam lingkup tugas perencanaan, evaluasi, dan pelaporan.
A17: II. | B17: TUGAS DAN TANGGUNG JAWAB UTAMA
B18: A. | C18: URAIAN TUGAS
C19: 1 | D19: ='URAIAN JABATAN'!C35 -> Melakukan penatausahaan surat dan dokumen yang meliputi penerimaan, penelitian, verifikasi, pencatatan, dan distribusi surat dan dokumen dalam lingkup tugas perencanaan, evaluasi, dan pelaporan
C20: 2 | D20: ='URAIAN JABATAN'!C36 -> Menyusun dan menyediakan surat dan dokumen sesuai tata naskah dinas yang berlaku dalam lingkup tugas perencanaan, evaluasi, dan pelaporan
C21: 3 | D21: ='URAIAN JABATAN'!C37 -> Melakukan penyimpanan dan pengarsipan sesuai dengan tata kelola arsip terhadap surat dan dokumen dalam lingkup tugas perencanaan, evaluasi, dan pelaporan
C22: 4 | D22: ='URAIAN JABATAN'!C38 -> Melakukan kegiatan pelayanan publik dalam lingkup tugas perencanaan, evaluasi, dan pelaporan
C23: 5 | D23: ='URAIAN JABATAN'!C39 -> Melaksanakan pemberian dukungan teknis terhadap pelaksanaan tugas dan fungsi unit organisasi berupa penyiapan dan penyusunan dokumen, data, bahan, dan perlengkapan kegiatan dalam rangka pencapaian target kinerja organisasi.
C24: 6 | D24: ='URAIAN JABATAN'!C40 -> Menyusun laporan pelaksanaan tugas dan menyampaikan kepada pimpinan sebagai wujud akuntabilitas dan pertanggungjawaban pelaksanaan tugas.
C25: 7 | D25: ='URAIAN JABATAN'!C41 -> Melaksanakan tugas kedinasan lain yang diberikan oleh pimpinan, baik lisan maupun tertulis sebagai wujud loyalitas dan kerjasama yang baik.
B26: B. | C26: TANGGUNG JAWAB
C27: 1 | D27: ='URAIAN JABATAN'!C75 -> Keakuratan dan kelengkapan Laporan kegiatan penatausahaan surat dan dokumen dalam lingkup tugas perencanaan, evaluasi, dan pelaporan
C28: 2 | D28: ='URAIAN JABATAN'!C76 -> Keakuratan dan kelengkapan Dokumen dan surat dalam lingkup tugas perencanaan, evaluasi, dan pelaporan
C29: 3 | D29: ='URAIAN JABATAN'!C77 -> Keakuratan dan kelengkapan Arsip surat dan dokumen dalam lingkup tugas perencanaan, evaluasi, dan pelaporan
C30: 4 | D30: ='URAIAN JABATAN'!C78 -> Keakuratan dan kelengkapan Laporan kegiatan pelayanan publik dalam lingkup tugas perencanaan, evaluasi, dan pelaporan
C31: 5 | D31: ='URAIAN JABATAN'!C79 -> Kelancaran pelaksanaan kegiatan serta keakuratan dan kelengkapan dokumen, bahan, dan perlengkapan kegiatan tugas dan fungsi unit organisasi
C32: 6 | D32: ='URAIAN JABATAN'!C80 -> Keakuratan dan kelengkapan laporan bulanan pelaksanaan tugas dan kegiatan
C33: 7 | D33: ='URAIAN JABATAN'!C81 -> Keakuratan dan kelengkapan laporan tugas tambahan/kedinasan lainnya
A35: III. | B35: HASIL KERJA JABATAN
B36: 1 | C36: ='URAIAN JABATAN'!C65 -> Laporan kegiatan penatausahaan surat dan dokumen dalam lingkup tugas perencanaan, evaluasi, dan pelaporan
B37: 2 | C37: ='URAIAN JABATAN'!C66 -> Dokumen dan surat dalam lingkup tugas perencanaan, evaluasi, dan pelaporan
B38: 3 | C38: ='URAIAN JABATAN'!C67 -> Arsip surat dan dokumen dalam lingkup tugas perencanaan, evaluasi, dan pelaporan
B39: 4 | C39: ='URAIAN JABATAN'!C68 -> Laporan kegiatan pelayanan publik dalam lingkup tugas perencanaan, evaluasi, dan pelaporan
B40: 5 | C40: ='URAIAN JABATAN'!C69 -> Dokumen, bahan, dan perlengkapan kegiatan tugas dan fungsi unit organisasi
B41: 6 | C41: ='URAIAN JABATAN'!C70 -> Laporan bulanan pelaksanaan tugas dan kegiatan
B42: 7 | C42: ='URAIAN JABATAN'!C71 -> Laporan tugas tambahan/kedinasan lainnya
A44: IV. | B44: TINGKAT FAKTOR
B45: FAKTOR 1 | E45: : | F45: PENGETAHUAN YANG DIBUTUHKAN JABATAN | U45: ( | V45: 1 - | W45: =DATA!D21 -> 3 | X45: = | Y45: =IF(AND(W45=1),50,IF(AND(W45=2),200,IF(AND(W45=3),350,IF(AND(W45=4),550,IF(AND(W45=5),750,IF(AND(W45=6),950,IF(AND(W45=7),1250,0))))))) -> 350 | AA45: ) | AC45: FAC 1 | AD45: TESfac1-1 | AE45: TESfac1-2 | AF45: TESfac1-3 | AG45: TESfac1-4 | AH45: TESfac1-5 | AI45: TESfac1-6 | AJ45: TESfac1-7 | AR45: unit
F46: ="Jabatan "&$H$9&" "&AR46&" "&AC46 -> Jabatan Pengadministrasi Perkantoran Sekretariat Dinas Penanaman Modal dan Pelayanan Terpadu Satu Pintu memerlukan pengetahuan tentang sejumlah peraturan, prosedur, dan operasi, yang membutuhkan pelatihan dan pengalaman yang cukup untuk melaksanakan pekerjaan klerek dan menyelesaikan masalah yang muncul serta memerlukan memerlukan keterampilan, yang membutuhkan pelatihan dan pengalaman yang cukup, untuk mengoperasikan dan menyesuaikan peralatan dalam berbagai tujuan terkait yang bidang tugas. | AC46: =IF(W45=1,AD46,IF(W45=2,AE46,IF(W45=3,AF46,IF(W45=4,AG46,IF(W45=5,AH46,IF(W45=6,AI46,IF(W45=7,AJ46,"0"))))))) -> memerlukan pengetahuan tentang sejumlah peraturan, prosedur, dan operasi, yang membutuhkan pelatihan dan pengalaman yang cukup untuk melaksanakan pekerjaan klerek dan menyelesaikan masalah yang muncul serta memerlukan memerlukan keterampilan, yang membutuhkan pelatihan dan pengalaman yang cukup, untuk mengoperasikan dan menyesuaikan peralatan dalam berbagai tujuan terkait yang bidang tugas. | AD46: memerlukan pengetahuan tentang tugas atau operasi yang sederhana, rutin, atau berulang, yang secara khusus mengikuti instruksi langkah demi langkah, dan sedikit atau sama sekali tidak membutuhkan pelatihan atau pengalaman sebelumnya serta memerlukan keterampilan untuk menjalankan peralatan sederhana atau peralatan yang beroperasi secara berkala, yang sedikit atau sama sekali tidak membutuhkan pelatihan atau pengalaman terkait bidang tugas. | AE46: memerlukan pengetahuan tentang prosedur, peraturan, atau operasi dasar atau umum, yang secara khusus membutuhkan sedikit pelatihan atau pengalaman sebelumnya terkait bidang tugas. | AF46: memerlukan pengetahuan tentang sejumlah peraturan, prosedur, dan operasi, yang membutuhkan pelatihan dan pengalaman yang cukup untuk melaksanakan pekerjaan klerek dan menyelesaikan masalah yang muncul serta memerlukan memerlukan keterampilan, yang membutuhkan pelatihan dan pengalaman yang cukup, untuk mengoperasikan dan menyesuaikan peralatan dalam berbagai tujuan terkait yang bidang tugas. | AG46: memerlukan pengetahuan tentang sejumlah peraturan, prosedur, atau operasi, serta standar prosedur dibidang teknik, yang membutuhkan pelatihan atau pengalaman luas untuk melaksanakan berbagai pekerjaan yang tidak standar dan saling berhubungan, dan menyelesaikan berbagai macam masalah sesuai bidang tugasnya. | AH46: memerlukan pengetahuan dasar tentang prinsip, konsep, dan metodologi pekerjaan administratif dan keterampilan dalam penerapan pengetahuan tersebut untuk melaksanakan tugas, operasi, atau prosedur dasar terkait bidang tugas. | AI46: memerlukan pengetahuan dasar tentang prinsip, konsep, dan metodologi pekerjaan profesional atau pekerjaan administratif, dalam penerapan pengetahuan tersebut untuk melaksanakan tugas, operasi, atau prosedur dasar serta pengembangan pengetahuan profesional atau pengetahuan administratif yang diperoleh melalui pengalaman atau lulus sarjana yang relevan, yang memberikan keahlian dalam pelaksanaan tugas, operasi dan prosedur pekerjaan yang secara signifikan lebih sulit dan rumit. | AJ46: memerlukan pengetahuan tentang berbagai konsep, prinsip, dan praktek pekerjaan profesional atau administratif, yang dapat diperoleh melalui pendidikan diatas sarjana atau pengalaman yang luas, dan keterampilan didalam penerapan pengetahuan tersebut dalam pekerjaan yang sulit dan kompleks. | AR46: =IF($H$11="-",$H$12,$H$11) -> Sekretariat Dinas Penanaman Modal dan Pelayanan Terpadu Satu Pintu
B47: FAKTOR 2 | E47: : | F47: PENGAWASAN PENYELIA | U47: ( | V47: 2 - | W47: =DATA!D22 -> 1 | X47: = | Y47: =IF(AND(W47=1),25,IF(AND(W47=2),125,IF(AND(W47=3),275,IF(AND(W47=4),450,IF(AND(W47=5),650,0))))) -> 25 | AA47: ) | AC47: FAC2A | AD47: FAC2B | AE47: TESFAC2A_1 | AF47: TESFAC2B_1 | AG47: TESFAC2A_2 | AH47: TESFAC2B_2 | AI47: TESFAC2A_3 | AJ47: TESFAC2B_3 | AK47: TESFAC2A_4 | AL47: TESFAC2B_4 | AM47: TESFAC2A_5 | AN47: TESFAC2B_5
F48: =AC48 -> Penyelia membuat tugas tertentu disertai dengan instruksi yang jelas, terperinci, dan spesifik Untuk tugas sejenis dan berulang. | AC48: =IF(W47=1,AE48,IF(W47=2,AG48,IF(W47=3,AI48,IF(W47=4,AK48,IF(W47=5,AM48,0))))) -> Penyelia membuat tugas tertentu disertai dengan instruksi yang jelas, terperinci, dan spesifik Untuk tugas sejenis dan berulang. | AD48: =IF(W47=1,AF48,IF(W47=2,AH48,IF(W47=3,AJ48,IF(W47=4,AL48,IF(W47=5,AN48,0))))) -> bekerja sesuai instruksi dan berkonsultasi dengan penyelia sebagaimana dibutuhkan untuk semua persoalan yang tidak spesifik dicakup di dalam instruksi atau pedoman, pekerjaan diawasi dengan teliti dan dalam situasi tertentu, penyelia melakukan peninjauan pekerjaan, termasuk pengecekan kemajuan pekerjaan atau peninjauan pekerjaan yang telah selesai untuk tujuan keakuratan, kecukupan, dan ketaatan pada instruksi dan prosedur yang ditetapkan. | AE48: Penyelia membuat tugas tertentu disertai dengan instruksi yang jelas, terperinci, dan spesifik Untuk tugas sejenis dan berulang. | AF48: bekerja sesuai instruksi dan berkonsultasi dengan penyelia sebagaimana dibutuhkan untuk semua persoalan yang tidak spesifik dicakup di dalam instruksi atau pedoman, pekerjaan diawasi dengan teliti dan dalam situasi tertentu, penyelia melakukan peninjauan pekerjaan, termasuk pengecekan kemajuan pekerjaan atau peninjauan pekerjaan yang telah selesai untuk tujuan keakuratan, kecukupan, dan ketaatan pada instruksi dan prosedur yang ditetapkan. | AG48: Penyelia memberikan tugas berkelanjutan atau tugas tertentu dengan mengindikasikan secara umum apa yang harus diselesaikan, batasan, kualitas, dan kuantitas yang diharapkan, batas waktu dan prioritas tugas. Penyelia memberikan tambahan instruksi untuk tugas baru, sulit, atau yang tidak biasa, termasuk metode kerja yang disarankan atau saran pada sumber materi yang tersedia. | AH48: menggunakan inisiatif dalam melaksanakan tugas yang berulang secara mandiri tanpa instruksi spesifik, tapi melaporkan deviasi, masalah, dan situasi yang tidak lazim yang tidak dicakup dalam instruksi kepada penyelia untuk membuat keputusan atau meminta bantuan.Penyelia menjamin bahwa pekerjaan yang telah selesai dan metode yang digunakan adalah secara teknik akurat dan memenuhi instruksi atau prosedur yang ada. | AI48: Penyelia memberikan tugas dengan tujuan, prioritas, dan batas waktu yang ditentukan, dan membantu pegawai pada situasi yang tidak lazim dan belum ada contoh yang jelas. | AJ48: merencanakan dan melaksanakan langkah-langkah yang sesuai dan menangani masalah dan deviasi pekerjaan sesuai dengan instruksi, kebijakan, latihan sebelumnya, atau praktek yang berlaku.Pekerjaan yang telah selesai biasanya dievaluasi untuk kesesuaian teknik, kelayakan dan kesesuaian pada kebijakan dan persyaratan. Metode yang digunakan untuk mendapatkan hasil akhir biasanya tidak ditinjau secara terperinci. | AK48: Penyelia menentukan tujuan dan sumber daya yang tersedia. Pegawai dan penyelia berkonsultasi mengembangkan batas waktu, proyek, dan pekerjaan yang harus dilakukan. | AL48: mempunyai keahlian dalam pekerjaan, bertanggungjawab untuk perencanaan dan pelaksanaan tugas, pemecahan sebagian besar konflik yang timbul, pengkoordinasian pekerjaan dengan yang lainnya sebagaimana diperlukan, dan menginterpretasikan kebijakan atas inisiatif sendiri sesuai dengan tujuan yang ditetapkan serta menginformasikan kepada penyelia terkait kemajuan dan masalah kontroversial yang terjadi. | AM48: Penyelia memberikan tugas dengan petunjuk dalam terminologi misi atau fungsi yang didefenisikan dengan luas. | AN48: mempunyai tanggungjawab untuk perencanaan, desain, dan pelaksanaan program, proyek, studi, atau pekerjaan secara mandiri sesuai bidang tugas.
F49: ="Jabatan "&H9&" "&AD48 -> Jabatan Pengadministrasi Perkantoran bekerja sesuai instruksi dan berkonsultasi dengan penyelia sebagaimana dibutuhkan untuk semua persoalan yang tidak spesifik dicakup di dalam instruksi atau pedoman, pekerjaan diawasi dengan teliti dan dalam situasi tertentu, penyelia melakukan peninjauan pekerjaan, termasuk pengecekan kemajuan pekerjaan atau peninjauan pekerjaan yang telah selesai untuk tujuan keakuratan, kecukupan, dan ketaatan pada instruksi dan prosedur yang ditetapkan.
...

Sheet INFOJAB
A5: PEMERINTAH KOTA SEMARANG
A7: INFORMASI JABATAN
A9: 1. | B9: NAMA JABATAN | G9: : | H9: ='URAIAN JABATAN'!G9 -> Pengadministrasi Perkantoran
A10: 2. | B10: KODE JABATAN | G10: : | H10: ='URAIAN JABATAN'!G10 -> 23.1.1.0.8
A11: 3. | B11: UNIT KERJA | G11: :
B12: a. | C12: JPT Utama | G12: : | H12: -
B13: b. | C13: JPT Madya | G13: : | H13: -
B14: c. | C14: JPT Pratama/UOBK | G14: : | H14: ='URAIAN JABATAN'!G12 -> Dinas Penanaman Modal dan Pelayanan Terpadu Satu Pintu
B15: d. | C15: Administrator | G15: : | H15: ='URAIAN JABATAN'!G13 -> Sekretariat Dinas Penanaman Modal dan Pelayanan Terpadu Satu Pintu
B16: e. | C16: Pengawas | G16: : | H16: ='URAIAN JABATAN'!G14 -> -
B17: f. | C17: Pelaksana | G17: : | H17: -
B18: g. | C18: Jabatan Fungsional | G18: : | H18: -
A19: 4. | B19: IKHTISAR JABATAN | G19: :
B20: ='URAIAN JABATAN'!B33 -> Melaksanakan kegiatan dukungan administrasi perkantoran, pemerintahan, dan pelayanan publik dalam lingkup tugas perencanaan, evaluasi, dan pelaporan.
A21: 5. | B21: KUALIFIKASI JABATAN | G21: :
B22: a. | C22: Pendidikan Formal | I22: : | J22: ='URAIAN JABATAN'!I117 -> SLTA Sederajat/D-3(Diploma-Tiga) bidang yang relevan dengan tugas jabatan
B23: b. | C23: Pendidikan dan Pelatihan | I23: : | J23: Diklat teknis sesuai bidang tugas
B24: c. | C24: Pengalaman kerja | I24: : | J24: =DATA!D33 -> -
A25: 6. | B25: TUGAS POKOK | F25: :
B26: NO | C26: URAIAN TUGAS | I26: HASIL KERJA | O26: JUMLAH HASIL | R26: WAKTU PENYELESAIAN (JAM) | T26: WAKTU EFEKTIF | V26: KEBUTUHAN PEGAWAI
B27: 1 | C27: ='URAIAN JABATAN'!C35 -> Melakukan penatausahaan surat dan dokumen yang meliputi penerimaan, penelitian, verifikasi, pencatatan, dan distribusi surat dan dokumen dalam lingkup tugas perencanaan, evaluasi, dan pelaporan | I27: ='URAIAN JABATAN'!C65 -> Laporan kegiatan penatausahaan surat dan dokumen dalam lingkup tugas perencanaan, evaluasi, dan pelaporan | O27: =ABK!K10 -> 240 | R27: =ABK!L10 -> 1,5 | T27: =ABK!M10 -> 1250 | V27: =O27*R27/T27 -> #VALUE!
B28: 2 | C28: ='URAIAN JABATAN'!C36 -> Menyusun dan menyediakan surat dan dokumen sesuai tata naskah dinas yang berlaku dalam lingkup tugas perencanaan, evaluasi, dan pelaporan | I28: ='URAIAN JABATAN'!C66 -> Dokumen dan surat dalam lingkup tugas perencanaan, evaluasi, dan pelaporan | O28: =ABK!K11 -> 48 | R28: =ABK!L11 -> 4,5 | T28: =ABK!M11 -> 1250 | V28: =O28*R28/T28 -> #VALUE!
B29: 3 | C29: ='URAIAN JABATAN'!C37 -> Melakukan penyimpanan dan pengarsipan sesuai dengan tata kelola arsip terhadap surat dan dokumen dalam lingkup tugas perencanaan, evaluasi, dan pelaporan | I29: ='URAIAN JABATAN'!C67 -> Arsip surat dan dokumen dalam lingkup tugas perencanaan, evaluasi, dan pelaporan | O29: =ABK!K12 -> 12 | R29: =ABK!L12 -> 3 | T29: =ABK!M12 -> 1250 | V29: =O29*R29/T29 -> 0.0288
B30: 4 | C30: ='URAIAN JABATAN'!C38 -> Melakukan kegiatan pelayanan publik dalam lingkup tugas perencanaan, evaluasi, dan pelaporan | I30: ='URAIAN JABATAN'!C68 -> Laporan kegiatan pelayanan publik dalam lingkup tugas perencanaan, evaluasi, dan pelaporan | O30: =ABK!K13 -> 240 | R30: =ABK!L13 -> 1,5 | T30: =ABK!M13 -> 1250 | V30: =O30*R30/T30 -> #VALUE!
B31: 5 | C31: ='URAIAN JABATAN'!C39 -> Melaksanakan pemberian dukungan teknis terhadap pelaksanaan tugas dan fungsi unit organisasi berupa penyiapan dan penyusunan dokumen, data, bahan, dan perlengkapan kegiatan dalam rangka pencapaian target kinerja organisasi. | I31: ='URAIAN JABATAN'!C69 -> Dokumen, bahan, dan perlengkapan kegiatan tugas dan fungsi unit organisasi | O31: =ABK!K14 -> 240 | R31: =ABK!L14 -> 1 | T31: =ABK!M14 -> 1250 | V31: =O31*R31/T31 -> 0.192
B32: 6 | C32: ='URAIAN JABATAN'!C40 -> Menyusun laporan pelaksanaan tugas dan menyampaikan kepada pimpinan sebagai wujud akuntabilitas dan pertanggungjawaban pelaksanaan tugas. | I32: ='URAIAN JABATAN'!C70 -> Laporan bulanan pelaksanaan tugas dan kegiatan | O32: =ABK!K15 -> 12 | R32: =ABK!L15 -> 3 | T32: =ABK!M15 -> 1250 | V32: =O32*R32/T32 -> 0.0288
B33: 7 | C33: ='URAIAN JABATAN'!C41 -> Melaksanakan tugas kedinasan lain yang diberikan oleh pimpinan, baik lisan maupun tertulis sebagai wujud loyalitas dan kerjasama yang baik. | I33: ='URAIAN JABATAN'!C71 -> Laporan tugas tambahan/kedinasan lainnya | O33: =ABK!K16 -> 2 | R33: =ABK!L16 -> 1,5 | T33: =ABK!M16 -> 1250 | V33: =O33*R33/T33 -> #VALUE!
B34: JUMLAH | R34: =(O27*R27)+(O28*R28)+(O29*R29)+(O30*R30)+(O33*R33)+(O31*R31)+(O32*R32) -> #VALUE! | V34: =SUM(V27:W33) -> #VALUE!
B35: JUMLAH PEGAWAI | V35: =ABK!N18 -> 1
A37: 7. | B37: HASIL KERJA | F37: :
B38: a. | C38: =I27 -> Laporan kegiatan penatausahaan surat dan dokumen dalam lingkup tugas perencanaan, evaluasi, dan pelaporan
B39: b. | C39: =I28 -> Dokumen dan surat dalam lingkup tugas perencanaan, evaluasi, dan pelaporan
B40: c. | C40: =I29 -> Arsip surat dan dokumen dalam lingkup tugas perencanaan, evaluasi, dan pelaporan
B41: d. | C41: =I30 -> Laporan kegiatan pelayanan publik dalam lingkup tugas perencanaan, evaluasi, dan pelaporan
B42: e. | C42: =I31 -> Dokumen, bahan, dan perlengkapan kegiatan tugas dan fungsi unit organisasi
B43: f. | C43: =I32 -> Laporan bulanan pelaksanaan tugas dan kegiatan
B44: g. | C44: =I33 -> Laporan tugas tambahan/kedinasan lainnya
A46: 8. | B46: BAHAN KERJA | F46: :
B48: No | C48: Bahan Kerja | N48: Penggunaan Dalam Tugas
B49: 1 | C49: ='URAIAN JABATAN'!C46 -> Surat/dokumen yang terkait dengan bidang tugas. | N49: ='URAIAN JABATAN'!N46 -> Dasar dan acuan dalam pelaksanaan tugas.
...
